<?xml version="1.0" encoding="utf-8"?>
<!-- =================================================================================== -->
<!-- |    This document was autogenerated by xacro from diff_drive.xacro               | -->
<!-- |    EDITING THIS FILE BY HAND IS NOT RECOMMENDED                                 | -->
<!-- =================================================================================== -->
<robot name="mighty1">
  <!--<xacro:arg name="model" default="Diff_Drive"/>
<xacro:include filename="$(find mighty_rover)/xacro/imu_macro.xacro" />-->
  <!-- /////////////////////////////////////////////////////////////////-->
  <!-- Include materials-->
  <material name="Black">
    <color rgba="0.0 0.0 0.0 1.0"/>
  </material>
  <material name="White">
    <color rgba="1.0 1.0 1.0 1.0"/>
  </material>
  <!-- /////////////////////////////////////////////////////-->
  <!-- ///////////////////////////////////////////////////-->
  <!-- ////////////////////////////////////////////////////-->
  <!--transmission block-->
  <!-- //////////////////////////////////////////////////// -->
  <!-- ////////////////////////////////////////////////////////////-->
  <!-- base_link-->
  <link name="base_link">
    <visual>
      <origin rpy="-1.57 0 1.57" xyz="0 0 0"/>
      <geometry>
        <mesh filename="package://diff_drive/meshes/base assembly.dae"/>
      </geometry>
    </visual>
    <collision>
      <origin rpy="-1.57 0 0" xyz="0 0 0"/>
      <geometry>
        <mesh filename="package://diff_drive/meshes/base assembly.dae"/>
      </geometry>
    </collision>
    <inertial>
      <mass value="5.0"/>
      <inertia ixx="1.0" ixy="0.0" ixz="0.0" iyy="1.0" iyz="0.0" izz="1.0"/>
    </inertial>
  </link>
  <gazebo reference="base_link">
    <turnGravityOff>false</turnGravityOff>
  </gazebo>
  <!-- ///////////////////      Wheels      ///////////////////////   -->
  <!--<xacro:macro name="body"parent="base_link" />
<xacro:wheel prefix="right" suffix="front" parent="base_link" X="1" Y="0" Z="-1"/>
<xacro:wheel prefix="right" suffix="back" parent="base_link" X="0" Y="1" Z="-1"/>
<xacro:wheel prefix="left" suffix="front" parent="base_link" X="1" Y="0" Z="1"/>
<xacro:wheel prefix="left" suffix="back" parent="base_link" X="0" Y="1" Z="1"/>-->
  <link name="right_front_wheel">
    <visual>
      <origin rpy="1.57 0 0" xyz="0 0 0"/>
      <geometry>
        <cylinder length="0.022" radius="0.011"/>
      </geometry>
      <material name="Black"/>
    </visual>
    <collision>
      <origin rpy="1.57 0 0" xyz="0 0 0"/>
      <geometry>
        <cylinder length="0.022" radius="0.011"/>
      </geometry>
    </collision>
    <inertial>
      <mass value="0.2"/>
      <inertia ixx="2.48722222222e-05" ixy="0.0" ixz="0.0" iyy="2.48722222222e-05" iyz="0.0" izz="3.36111111111e-05"/>
    </inertial>
  </link>
  <link name="right_front_wheel1">
    <visual>
      <origin rpy="0  1.57 0" xyz="0 0 0"/>
      <geometry>
        <mesh filename="package://diff_drive/meshes/tyre11.dae"/>
      </geometry>
      <material name="Black"/>
    </visual>
    <collision>
      <origin rpy="0 1.57 0" xyz="0 0 0"/>
      <geometry>
        <mesh filename="package://diff_drive/meshes/tyre11.dae"/>
      </geometry>
    </collision>
    <inertial>
      <mass value="0.2"/>
      <inertia ixx="0.000159316666667" ixy="0.0" ixz="0.0" iyy="0.000159316666667" iyz="0.0" izz="0.0003025"/>
    </inertial>
  </link>
  <gazebo reference="right_front_wheel1">
    <material>Gazebo/Black</material>
    <turnGravityOff>false</turnGravityOff>
  </gazebo>
  <joint name="right_front_wheel_joint1" type="fixed">
    <parent link="right_front_wheel"/>
    <child link="right_front_wheel1"/>
    <origin rpy="0 0 0" xyz="0 0 0"/>
  </joint>
  <gazebo reference="right_front_wheel">
    <mu1 value="200.0"/>
    <mu2 value="100.0"/>
    <kp value="10000000.0"/>
    <kd value="1.0"/>
    <material>Gazebo/Black</material>
  </gazebo>
  <joint name="right_front_wheel_joint" type="continuous">
    <parent link="base_link"/>
    <child link="right_front_wheel"/>
    <origin rpy="0 0 0" xyz="0.062 -0.115  0.015"/>
    <axis xyz="0 1 0"/>
    <limit effort="100" velocity="100"/>
    <dynamics damping="0.0" friction="0.0"/>
  </joint>
  

--

--

--

 
  <transmission name="right_front_wheel_trans">
    <type>transmission_interface/SimpleTransmission</type>
    <actuator name="right_front_wheel_motor">
      <hardwareInterface>EffortJointInterface</hardwareInterface>
      <mechanicalReduction>1</mechanicalReduction>
    </actuator>
    <joint name="right_front_wheel_joint">
      <hardwareInterface>VelocityJointInterface</hardwareInterface>
    </joint>
  </transmission>
  <link name="right_back_wheel">
    <visual>
      <origin rpy="1.57 0 0" xyz="0 0 0"/>
      <geometry>
        <cylinder length="0.022" radius="0.011"/>
      </geometry>
      <material name="Black"/>
    </visual>
    <collision>
      <origin rpy="1.57 0 0" xyz="0 0 0"/>
      <geometry>
        <cylinder length="0.022" radius="0.011"/>
      </geometry>
    </collision>
    <inertial>
      <mass value="0.2"/>
      <inertia ixx="2.48722222222e-05" ixy="0.0" ixz="0.0" iyy="2.48722222222e-05" iyz="0.0" izz="3.36111111111e-05"/>
    </inertial>
  </link>
  <link name="right_back_wheel1">
    <visual>
      <origin rpy="0  1.57 0" xyz="0 0 0"/>
      <geometry>
        <mesh filename="package://diff_drive/meshes/tyre11.dae"/>
      </geometry>
      <material name="Black"/>
    </visual>
    <collision>
      <origin rpy="0 1.57 0" xyz="0 0 0"/>
      <geometry>
        <mesh filename="package://diff_drive/meshes/tyre11.dae"/>
      </geometry>
    </collision>
    <inertial>
      <mass value="0.2"/>
      <inertia ixx="0.000159316666667" ixy="0.0" ixz="0.0" iyy="0.000159316666667" iyz="0.0" izz="0.0003025"/>
    </inertial>
  </link>
  <gazebo reference="right_back_wheel1">
    <material>Gazebo/Black</material>
    <turnGravityOff>false</turnGravityOff>
  </gazebo>
  <joint name="right_back_wheel_joint1" type="fixed">
    <parent link="right_back_wheel"/>
    <child link="right_back_wheel1"/>
    <origin rpy="0 0 0" xyz="0 0 0"/>
  </joint>
  <gazebo reference="right_back_wheel">
    <mu1 value="200.0"/>
    <mu2 value="100.0"/>
    <kp value="10000000.0"/>
    <kd value="1.0"/>
    <material>Gazebo/Black</material>
  </gazebo>
  <joint name="right_back_wheel_joint" type="continuous">
    <parent link="base_link"/>
    <child link="right_back_wheel"/>
    <origin rpy="0 0 0" xyz="-0.058 -0.115  0.015"/>
    <axis xyz="0 1 0"/>
    <limit effort="100" velocity="100"/>
    <dynamics damping="0.0" friction="0.0"/>
  </joint>
  

--

--

--

 
  <transmission name="right_back_wheel_trans">
    <type>transmission_interface/SimpleTransmission</type>
    <actuator name="right_back_wheel_motor">
      <hardwareInterface>EffortJointInterface</hardwareInterface>
      <mechanicalReduction>1</mechanicalReduction>
    </actuator>
    <joint name="right_back_wheel_joint">
      <hardwareInterface>VelocityJointInterface</hardwareInterface>
    </joint>
  </transmission>
  <link name="left_front_wheel">
    <visual>
      <origin rpy="1.57 0 0" xyz="0 0 0"/>
      <geometry>
        <cylinder length="0.022" radius="0.011"/>
      </geometry>
      <material name="Black"/>
    </visual>
    <collision>
      <origin rpy="1.57 0 0" xyz="0 0 0"/>
      <geometry>
        <cylinder length="0.022" radius="0.011"/>
      </geometry>
    </collision>
    <inertial>
      <mass value="0.2"/>
      <inertia ixx="2.48722222222e-05" ixy="0.0" ixz="0.0" iyy="2.48722222222e-05" iyz="0.0" izz="3.36111111111e-05"/>
    </inertial>
  </link>
  <link name="left_front_wheel1">
    <visual>
      <origin rpy="0  1.57 0" xyz="0 0 0"/>
      <geometry>
        <mesh filename="package://diff_drive/meshes/tyre11.dae"/>
      </geometry>
      <material name="Black"/>
    </visual>
    <collision>
      <origin rpy="0 1.57 0" xyz="0 0 0"/>
      <geometry>
        <mesh filename="package://diff_drive/meshes/tyre11.dae"/>
      </geometry>
    </collision>
    <inertial>
      <mass value="0.2"/>
      <inertia ixx="0.000159316666667" ixy="0.0" ixz="0.0" iyy="0.000159316666667" iyz="0.0" izz="0.0003025"/>
    </inertial>
  </link>
  <gazebo reference="left_front_wheel1">
    <material>Gazebo/Black</material>
    <turnGravityOff>false</turnGravityOff>
  </gazebo>
  <joint name="left_front_wheel_joint1" type="fixed">
    <parent link="left_front_wheel"/>
    <child link="left_front_wheel1"/>
    <origin rpy="0 0 0" xyz="0 0 0"/>
  </joint>
  <gazebo reference="left_front_wheel">
    <mu1 value="200.0"/>
    <mu2 value="100.0"/>
    <kp value="10000000.0"/>
    <kd value="1.0"/>
    <material>Gazebo/Black</material>
  </gazebo>
  <joint name="left_front_wheel_joint" type="continuous">
    <parent link="base_link"/>
    <child link="left_front_wheel"/>
    <origin rpy="0 0 0" xyz="0.062 0.115  0.015"/>
    <axis xyz="0 1 0"/>
    <limit effort="100" velocity="100"/>
    <dynamics damping="0.0" friction="0.0"/>
  </joint>
  

--

--

--

 
  <transmission name="left_front_wheel_trans">
    <type>transmission_interface/SimpleTransmission</type>
    <actuator name="left_front_wheel_motor">
      <hardwareInterface>EffortJointInterface</hardwareInterface>
      <mechanicalReduction>1</mechanicalReduction>
    </actuator>
    <joint name="left_front_wheel_joint">
      <hardwareInterface>VelocityJointInterface</hardwareInterface>
    </joint>
  </transmission>
  <link name="left_back_wheel">
    <visual>
      <origin rpy="1.57 0 0" xyz="0 0 0"/>
      <geometry>
        <cylinder length="0.022" radius="0.011"/>
      </geometry>
      <material name="Black"/>
    </visual>
    <collision>
      <origin rpy="1.57 0 0" xyz="0 0 0"/>
      <geometry>
        <cylinder length="0.022" radius="0.011"/>
      </geometry>
    </collision>
    <inertial>
      <mass value="0.2"/>
      <inertia ixx="2.48722222222e-05" ixy="0.0" ixz="0.0" iyy="2.48722222222e-05" iyz="0.0" izz="3.36111111111e-05"/>
    </inertial>
  </link>
  <link name="left_back_wheel1">
    <visual>
      <origin rpy="0  1.57 0" xyz="0 0 0"/>
      <geometry>
        <mesh filename="package://diff_drive/meshes/tyre11.dae"/>
      </geometry>
      <material name="Black"/>
    </visual>
    <collision>
      <origin rpy="0 1.57 0" xyz="0 0 0"/>
      <geometry>
        <mesh filename="package://diff_drive/meshes/tyre11.dae"/>
      </geometry>
    </collision>
    <inertial>
      <mass value="0.2"/>
      <inertia ixx="0.000159316666667" ixy="0.0" ixz="0.0" iyy="0.000159316666667" iyz="0.0" izz="0.0003025"/>
    </inertial>
  </link>
  <gazebo reference="left_back_wheel1">
    <material>Gazebo/Black</material>
    <turnGravityOff>false</turnGravityOff>
  </gazebo>
  <joint name="left_back_wheel_joint1" type="fixed">
    <parent link="left_back_wheel"/>
    <child link="left_back_wheel1"/>
    <origin rpy="0 0 0" xyz="0 0 0"/>
  </joint>
  <gazebo reference="left_back_wheel">
    <mu1 value="200.0"/>
    <mu2 value="100.0"/>
    <kp value="10000000.0"/>
    <kd value="1.0"/>
    <material>Gazebo/Black</material>
  </gazebo>
  <joint name="left_back_wheel_joint" type="continuous">
    <parent link="base_link"/>
    <child link="left_back_wheel"/>
    <origin rpy="0 0 0" xyz="-0.058 0.115  0.015"/>
    <axis xyz="0 1 0"/>
    <limit effort="100" velocity="100"/>
    <dynamics damping="0.0" friction="0.0"/>
  </joint>
  

--

--

--

 
  <transmission name="left_back_wheel_trans">
    <type>transmission_interface/SimpleTransmission</type>
    <actuator name="left_back_wheel_motor">
      <hardwareInterface>EffortJointInterface</hardwareInterface>
      <mechanicalReduction>1</mechanicalReduction>
    </actuator>
    <joint name="left_back_wheel_joint">
      <hardwareInterface>VelocityJointInterface</hardwareInterface>
    </joint>
  </transmission>
  <!--///////////////////////////////////////////////////////////////// -->
  <joint name="imu_joint" type="fixed">
    <parent link="base_link"/>
    <child link="imu_link"/>
    <origin rpy="0 0 0" xyz="0 0 0"/>
  </joint>
  <link name="imu_link"/>
  <gazebo reference="imu_link">
    <gravity>true</gravity>
    <sensor name="imu_sensor" type="imu">
      <always_on>true</always_on>
      <update_rate>100</update_rate>
      <visualize>true</visualize>
      <topic>data</topic>
      <plugin filename="libgazebo_ros_imu_sensor.so" name="imu_plugin">
        <topicName>imu/data</topicName>
        <bodyName>imu_link</bodyName>
        <updateRateHZ>10.0</updateRateHZ>
        <gaussianNoise>0.0</gaussianNoise>
        <xyzOffset>0 0 0</xyzOffset>
        <rpyOffset>0 0 0</rpyOffset>
        <frameName>mighty1/imu_link</frameName>
      </plugin>
      <pose>0 0 0 0 0 0</pose>
    </sensor>
  </gazebo>
  <!--<link name="hokuyo_sensor">
  <visual>
    <origin xyz="0 0 0" rpy="0 0 0"/>
   <geometry>
     <box size="0.05 0.05 0.05"/>
   </geometry>
   <material name="Blue"/>
   </visual>
 </link>

<joint name="hokuyo_joint" type="fixed">
  <origin xyz="0.07 0 0.08" rpy="0 0 0"/>
  <parent link="base_link"/>
  <child link="hokuyo_sensor"/>
</joint>

<gazebo reference="hokuyo_sensor">
  <material>Gazebo/Blue</material>
  <turnGravityOff>false</turnGravityOff>
  <sensor type="ray" name="base_link_hokuyo_sensor">
   <pose>0.025 0 0 0 0 0</pose>
   <visualize>false</visualize>
   <update_rate>40</update_rate>
   <ray>
     <scan>
       <horizontal>
         <samples>720</samples>
         <resolution>1</resolution>
         <min_angle>-1.57</min_angle>
         <max_angle>1.57</max_angle>  
        </horizontal>
      </scan>
     <range>
        <min>0.10</min>
        <max>10.0</max>
        <resolution>0.001</resolution>
      </range>
     </ray>
     <plugin name="gazebo_ros_head_hokuyo_controller" 
          filename="libgazebo_ros_laser.so">
        <topicName>/scan</topicName>
        <frameName>hokuyo_sensor</frameName>
       </plugin>
      </sensor>
     </gazebo>   -->
  <link name="hokuyo_sensor">
    <collision>
      <origin rpy="0 0 0" xyz="0 0 0"/>
      <geometry>
        <box size="0.1 0.1 0.1"/>
      </geometry>
    </collision>
    <visual>
      <origin rpy="0 0 0" xyz="0 0 0"/>
      <geometry>
        <mesh filename="package://rrbot_description/meshes/hokuyo.dae"/>
      </geometry>
    </visual>
    <inertial>
      <mass value="1e-5"/>
      <origin rpy="0 0 0" xyz="0 0 0"/>
      <inertia ixx="1e-6" ixy="0" ixz="0" iyy="1e-6" iyz="0" izz="1e-6"/>
    </inertial>
  </link>
  <joint name="hokuyo_joint" type="fixed">
    <parent link="base_link"/>
    <child link="hokuyo_sensor"/>
    <origin rpy="0 0 0" xyz="0.02 0 0.13"/>
  </joint>
  <gazebo reference="hokuyo_sensor">
    <sensor name="base_link_hokuyo_sensor" type="gpu_ray">
      <pose>0 0 0 0 0 0</pose>
      <visualize>true</visualize>
      <update_rate>40</update_rate>
      <ray>
        <scan>
          <horizontal>
            <samples>400</samples>
            <resolution>1</resolution>
            <min_angle>-2.61799387799</min_angle>
            <max_angle>2.61799387799</max_angle>
            --&gt;
            
            <!--<min_angle>-1.570796</min_angle>
            <max_angle>1.570796</max_angle>-->
          </horizontal>
        </scan>
        <range>
          <min>0.10</min>
          <max>30.0</max>
          <resolution>0.01</resolution>
        </range>
        <noise>
          <type>gaussian</type>
          <stddev>0.01</stddev>
        </noise>
      </ray>
      <plugin filename="libgazebo_ros_gpu_laser.so" name="gazebo_ros_lidar_controller">
        <topicName>/scan</topicName>
        <frameName>hokuyo_sensor</frameName>
      </plugin>
    </sensor>
  </gazebo>
  <!-- //////////////////////////////////////////////////////////////// -->
  <!-- ros_control plugin-->
  <gazebo>
    <plugin filename="libgazebo_ros_control.so" name="gazebo_ros_control">
      <robotNamespace>/</robotNamespace>
    </plugin>
  </gazebo>
  <link name="camera_link">
    <visual>
      <origin rpy="0 0 0" xyz="0 0 0"/>
      <geometry>
        <mesh filename="package://openni_description/mesh/kinect.dae"/>
      </geometry>
    </visual>
    <collision>
      <origin rpy="0 0 0" xyz="0.0 0.0 0.0"/>
      <geometry>
        <box size="0.07271 0.27794 0.073"/>
      </geometry>
    </collision>
  </link>
  <joint name="camera_joint" type="fixed">
    <origin rpy="0 0 1.57079637" xyz="0 0 0"/>
    <parent link="base_link"/>
    <child link="camera_link"/>
  </joint>
  <gazebo reference="multi_camera">
    <sensor name="stereo_camera" type="multicamera">
      <update_rate>30.0</update_rate>
      <camera name="left">
        <horizontal_fov>1.3962634</horizontal_fov>
        <image>
          <width>800</width>
          <height>800</height>
          <format>R8G8B8</format>
        </image>
        <clip>
          <near>0.02</near>
          <far>300</far>
        </clip>
        <noise>
          <type>gaussian</type>
          <mean>0.0</mean>
          <stddev>0.007</stddev>
        </noise>
      </camera>
      <camera name="right">
        <pose>0 -0.07 0 0 0 0</pose>
        <horizontal_fov>1.3962634</horizontal_fov>
        <image>
          <width>800</width>
          <height>800</height>
          <format>R8G8B8</format>
        </image>
        <clip>
          <near>0.02</near>
          <far>300</far>
        </clip>
        <noise>
          <type>gaussian</type>
          <mean>0.0</mean>
          <stddev>0.007</stddev>
        </noise>
      </camera>
      <plugin filename="libgazebo_ros_multicamera.so" name="stereo_camera_controller">
        <alwaysOn>true</alwaysOn>
        <updateRate>0.0</updateRate>
        <cameraName>multicamera/camera</cameraName>
        <imageTopicName>image_raw</imageTopicName>
        <cameraInfoTopicName>camera_info</cameraInfoTopicName>
        <frameName>left_camera_optical_frame</frameName>
        <!--<rightFrameName>right_camera_optical_frame</rightFrameName>-->
        <hackBaseline>0.07</hackBaseline>
        <distortionK1>0.0</distortionK1>
        <distortionK2>0.0</distortionK2>
        <distortionK3>0.0</distortionK3>
        <distortionT1>0.0</distortionT1>
        <distortionT2>0.0</distortionT2>
      </plugin>
    </sensor>
    <!-- <sensor type="depth" name="camera">
        <always_on>true</always_on>
        <visualize>true</visualize>
        <update_rate>20.0</update_rate>
        <camera>
          <horizontal_fov>${60.0*M_PI/180.0}</horizontal_fov>
          <image>
            <format>B8G8R8</format>
            <width>640</width>
            <height>480</height>
          </image>
          <clip>
            <near>0.05</near>
            <far>8.0</far>
          </clip>
        </camera>

        <plugin name="kinect_camera_controller" filename="libgazebo_ros_openni_kinect.so">
          <cameraName>camera</cameraName>
          <alwaysOn>true</alwaysOn>
          <updateRate>10</updateRate>
          <imageTopicName>rgb/image_raw</imageTopicName>
          <depthImageTopicName>depth/image_raw</depthImageTopicName>
          <pointCloudTopicName>depth/points</pointCloudTopicName>
          <cameraInfoTopicName>rgb/camera_info</cameraInfoTopicName>
          <depthImageCameraInfoTopicName>depth/camera_info</depthImageCameraInfoTopicName>
          <frameName>camera_link</frameName>
          <baseline>0.1</baseline>
          <distortion_k1>0.0</distortion_k1>
          <distortion_k2>0.0</distortion_k2>
          <distortion_k3>0.0</distortion_k3>
          <distortion_t1>0.0</distortion_t1>
          <distortion_t2>0.0</distortion_t2>
          <pointCloudCutoff>0.4</pointCloudCutoff>
        </plugin>
      </sensor> -->
  </gazebo>
</robot>

