<?xml version="1.0" encoding="utf-8"?>
<!-- =================================================================================== -->
<!-- |    This document was autogenerated by xacro from pf1.xacro                      | -->
<!-- |    EDITING THIS FILE BY HAND IS NOT RECOMMENDED                                 | -->
<!-- =================================================================================== -->
<robot name="pf1">
  <material name="base_link">
    <color rgba="0.95 0.95 1.0 1.0"/>
  </material>
  <material name="lidar">
    <color rgba="0.0 0.0 0.0 1.0"/>
  </material>
  <material name="frame">
    <color rgba="0.5 0.5 0.5 1.0"/>
  </material>
  <material name="gear">
    <color rgba="0.0 0.4 1.0 1.0"/>
  </material>
  <material name="motor">
    <color rgba="0.3 0.3 0.3 1.0"/>
  </material>
  <material name="wheel">
    <color rgba="0.15 0.15 0.15 1.0"/>
  </material>
  <!-- base_footprint-->
  <!-- <link name="base_footprint"/>

  <joint name="base_joint" type="fixed">
    <parent link="base_footprint"/>
    <child link="base_link"/>
    <origin xyz="0.0 0.0 0.47" rpy="0 0 0"/>
  </joint> -->
  <!-- base_link -->
  <link name="base_link">
    <visual>
      <geometry>
        <box size="0.45 0.39 0.2"/>
      </geometry>
      <origin rpy="0 0 0" xyz="0 0 0"/>
      <material name="base_link"/>
    </visual>
    <inertial>
      <mass value="5.0"/>
      <inertia ixx="1.0" ixy="0.0" ixz="0.0" iyy="1.0" iyz="0.0" izz="1.0"/>
    </inertial>
  </link>
  <gazebo reference="base_link">
    <turnGravityOff>false</turnGravityOff>
  </gazebo>
  <!-- imu_link -->
  <joint name="imu_link_to_base_link" type="fixed">
    <parent link="base_link"/>
    <child link="imu_link"/>
    <origin rpy="0 0 0" xyz="-0 0 0"/>
  </joint>
  <link name="imu_link">
    <visual>
      <origin rpy="0 0 0" xyz="0 0 0.0"/>
      <geometry>
        <cylinder length="0.01" radius="0.005"/>
      </geometry>
      <material name="lidar"/>
    </visual>
  </link>
  <gazebo reference="imu_link">
    <gravity>true</gravity>
    <sensor name="imu_sensor" type="imu">
      <always_on>true</always_on>
      <update_rate>100</update_rate>
      <visualize>true</visualize>
      <topic>data</topic>
      <plugin filename="libgazebo_ros_imu_sensor.so" name="imu_plugin">
        <topicName>imu/data</topicName>
        <bodyName>imu_link</bodyName>
        <updateRateHZ>10.0</updateRateHZ>
        <gaussianNoise>0.0</gaussianNoise>
        <xyzOffset>0 0 0</xyzOffset>
        <rpyOffset>0 0 0</rpyOffset>
        <frameName>imu_link</frameName>
      </plugin>
      <pose>0 0 0 0 0 0</pose>
    </sensor>
  </gazebo>
  <!-- base_scan -->
  <joint name="base_link_to_base_scan" type="fixed">
    <parent link="base_link"/>
    <child link="base_scan"/>
    <origin rpy="0 0 0" xyz="-0 0 0"/>
  </joint>
  <link name="base_scan">
    <visual>
      <origin rpy="0 0 0" xyz="0 0 0.0"/>
      <geometry>
        <cylinder length="0.01" radius="0.005"/>
      </geometry>
      <material name="lidar"/>
    </visual>
  </link>
  <!-- front_lidar -->
  <joint name="front_lidar_to_base_scan" type="fixed">
    <parent link="base_scan"/>
    <child link="front_lidar"/>
    <origin rpy="0 0 0" xyz="0.25 0 0"/>
  </joint>
  <link name="front_lidar">
    <visual>
      <origin rpy="0 0 0" xyz="0 0 0.0"/>
      <geometry>
        <cylinder length="0.05" radius="0.025"/>
      </geometry>
      <material name="lidar"/>
    </visual>
  </link>
  <gazebo reference="hokuyo_sensor">
    <sensor name="base_link_hokuyo_sensor" type="gpu_ray">
      <pose>0 0 0 0 0 0</pose>
      <!--visualize>true</visualize-->
      <visualize>false</visualize>
      <update_rate>40</update_rate>
      <ray>
        <scan>
          <horizontal>
            <samples>400</samples>
            <resolution>1</resolution>
            <min_angle>-2.61799387799</min_angle>
            <max_angle>2.61799387799</max_angle>
            <!--<min_angle>-1.570796</min_angle>
            <max_angle>1.570796</max_angle>-->
          </horizontal>
        </scan>
        <range>
          <min>0.10</min>
          <max>30.0</max>
          <resolution>0.01</resolution>
        </range>
        <noise>
          <type>gaussian</type>
          <stddev>0.01</stddev>
        </noise>
      </ray>
      <plugin filename="libgazebo_ros_gpu_laser.so" name="gazebo_ros_lidar_controller">
        <topicName>/scan</topicName>
        <frameName>front_lidar</frameName>
      </plugin>
    </sensor>
  </gazebo>
  <!-- leg_fl -->
  <joint name="frame1_fl_to_base_link" type="fixed">
    <parent link="base_link"/>
    <child link="frame1_fl"/>
    <origin rpy="0 0 0" xyz="0 0.14 -0.1"/>
  </joint>
  <link name="frame1_fl">
    <visual>
      <geometry>
        <box size="0.27 0.02 0.09"/>
      </geometry>
      <origin rpy="0 0 0" xyz="0.135 0 0"/>
      <material name="frame"/>
    </visual>
  </link>
  <joint name="frame2_fl_to_frame1_fl" type="fixed">
    <parent link="frame1_fl"/>
    <child link="frame2_fl"/>
    <origin rpy="0 0 0" xyz="0.23 0.02 -0.045"/>
  </joint>
  <link name="frame2_fl">
    <visual>
      <geometry>
        <box size="0.08 0.02 0.05"/>
      </geometry>
      <origin rpy="0 0 0" xyz="0 0 0"/>
      <material name="frame"/>
    </visual>
  </link>
  <!-- <joint name="gear_fl_to_frame2_fl" type="fixed">
    <parent link="frame2_fl"/>
    <child  link="gear_fl"/>
    <origin xyz="0 0.035 -0.06" rpy="0 0 0"/>
  </joint>
  <link name="gear_fl">
    <visual>
      <geometry>
        <box size="0.075 0.09 0.07"/>
      </geometry>
      <origin xyz="0 0 0" rpy="0 0 0"/>
      <material name="gear"/>
    </visual>
  </link>

  <joint name="frame3_fl_to_gear_fl" type="revolute">
    <parent link="gear_fl"/>
    <child  link="frame3_fl"/>
    <axis xyz="0 0 1"/>
    <origin xyz="0 0 -0.08" rpy="0 0 0"/>
    <limit lower="-3.1415" upper="3.1415" effort="0" velocity="0"/>
  </joint>
  <link name="frame3_fl">
    <visual>
      <geometry>
        <box size="0.075 0.09 0.09"/>
      </geometry>
      <origin xyz="0 0 0" rpy="0 0 0"/>
      <material name="frame"/>
    </visual>
  </link>

  <joint name="motor_fl_to_frame3_fl" type="fixed">
    <parent link="frame3_fl"/>
    <child  link="motor_fl"/>
    <origin xyz="0 -0.02 -0.09" rpy="0 0 0"/>
  </joint>
  <link name="motor_fl">
    <visual>
      <geometry>
        <box size="0.075 0.09 0.09"/>
      </geometry>
      <material name="motor"/>
    </visual>
  </link> 

 <joint name="wheel_fl_to_motor_fl" type="revolute">
    <parent link="motor_fl"/>
    <child  link="wheel_fl"/>
    <origin xyz="0 0.09 0" rpy="0 0 0"/>
    <axis xyz="0 1 0"/>
    <limit lower="-3.1415" upper="3.1415" effort="0" velocity="0"/>
  </joint>
  <link name="wheel_fl">
    <visual>
      <geometry>
        <cylinder length="0.09" radius="0.1"/>
      </geometry>
      <origin xyz="0 0 0" rpy="1.57 0 0"/>
      <material name="wheel"/>
    </visual>
  </link> -->
  <!-- leg_bl : mirror leg_fl to the y axis -->
  <joint name="frame1_bl_to_base_link" type="fixed">
    <parent link="base_link"/>
    <child link="frame1_bl"/>
    <origin rpy="0 0 0" xyz="0 0.14 -0.1"/>
  </joint>
  <link name="frame1_bl">
    <visual>
      <geometry>
        <box size="0.27 0.02 0.09"/>
      </geometry>
      <origin rpy="0 0 0" xyz="-0.135 0 0"/>
      <material name="frame"/>
    </visual>
  </link>
  <joint name="frame2_bl_to_frame1_bl" type="fixed">
    <parent link="frame1_bl"/>
    <child link="frame2_bl"/>
    <origin rpy="0 0 0" xyz="-0.23 0.02 -0.045"/>
  </joint>
  <link name="frame2_bl">
    <visual>
      <geometry>
        <box size="0.08 0.02 0.05"/>
      </geometry>
      <origin rpy="0 0 0" xyz="0 0 0"/>
      <material name="frame"/>
    </visual>
  </link>
  <!-- <joint name="gear_bl_to_frame2_bl" type="fixed">
    <parent link="frame2_bl"/>
    <child  link="gear_bl"/>
    <origin xyz="0 0.035 -0.06" rpy="0 0 0"/>
  </joint>
  <link name="gear_bl">
    <visual>
      <geometry>
        <box size="0.075 0.09 0.07"/>
      </geometry>
      <origin xyz="0 0 0" rpy="0 0 0"/>
      <material name="gear"/>
    </visual>
  </link>

  <joint name="frame3_bl_to_gear_bl" type="revolute">
    <parent link="gear_bl"/>
    <child  link="frame3_bl"/>
    <axis xyz="0 0 1"/>
    <origin xyz="0 0 -0.08" rpy="0 0 0"/>
    <limit lower="-3.1415" upper="3.1415" effort="0" velocity="0"/>
  </joint>
  <link name="frame3_bl">
    <visual>
      <geometry>
        <box size="0.075 0.09 0.09"/>
      </geometry>
      <origin xyz="0 0 0" rpy="0 0 0"/>
      <material name="frame"/>
    </visual>
  </link>

  <joint name="motor_bl_to_frame3_bl" type="fixed">
    <parent link="frame3_bl"/>
    <child  link="motor_bl"/>
    <origin xyz="0 -0.02 -0.09" rpy="0 0 0"/>
  </joint>
  <link name="motor_bl">
    <visual>
      <geometry>
        <box size="0.075 0.09 0.09"/>
      </geometry>
      <material name="motor"/>
    </visual>
  </link>

  <joint name="wheel_bl_to_motor_bl" type="revolute">
    <parent link="motor_bl"/>
    <child  link="wheel_bl"/>
    <origin xyz="0 0.09 0" rpy="0 0 0"/>
    <axis xyz="0 1 0"/>
    <limit lower="-3.1415" upper="3.1415" effort="0" velocity="0"/>
  </joint>
  <link name="wheel_bl">
    <visual>
      <geometry>
        <cylinder length="0.09" radius="0.1"/>
      </geometry>
      <origin xyz="0 0 0" rpy="1.57 0 0"/>
      <material name="wheel"/>
    </visual>
  </link> -->
  <!-- leg_fr -->
  <joint name="frame1_fr_to_base_link" type="fixed">
    <parent link="base_link"/>
    <child link="frame1_fr"/>
    <origin rpy="0 0 0" xyz="0 -0.14 -0.1"/>
  </joint>
  <link name="frame1_fr">
    <visual>
      <geometry>
        <box size="0.27 0.02 0.09"/>
      </geometry>
      <origin rpy="0 0 0" xyz="0.135 0 0"/>
      <material name="frame"/>
    </visual>
  </link>
  <joint name="frame2_fr_to_frame1_fr" type="fixed">
    <parent link="frame1_fr"/>
    <child link="frame2_fr"/>
    <origin rpy="0 0 0" xyz="0.23 -0.02 -0.045"/>
  </joint>
  <link name="frame2_fr">
    <visual>
      <geometry>
        <box size="0.08 0.02 0.05"/>
      </geometry>
      <origin rpy="0 0 0" xyz="0 0 0"/>
      <material name="frame"/>
    </visual>
  </link>
  <!-- <joint name="gear_fr_to_frame2_fr" type="fixed">
    <parent link="frame2_fr"/>
    <child  link="gear_fr"/>
    <origin xyz="0 -0.035 -0.06" rpy="0 0 0"/>
  </joint>
  <link name="gear_fr">
    <visual>
      <geometry>
        <box size="0.075 0.09 0.07"/>
      </geometry>
      <origin xyz="0 0 0" rpy="0 0 0"/>
      <material name="gear"/>
    </visual>
  </link>

  <joint name="frame3_fr_to_gear_fr" type="revolute">
    <parent link="gear_fr"/>
    <child  link="frame3_fr"/>
    <axis xyz="0 0 1"/>
    <origin xyz="0 0 -0.08" rpy="0 0 0"/>
    <limit lower="-3.1415" upper="3.1415" effort="0" velocity="0"/>
  </joint>
  <link name="frame3_fr">
    <visual>
      <geometry>
        <box size="0.075 0.09 0.09"/>
      </geometry>
      <origin xyz="0 0 0" rpy="0 0 0"/>
      <material name="frame"/>
    </visual>
  </link>

  <joint name="motor_fr_to_frame3_fr" type="fixed">
    <parent link="frame3_fr"/>
    <child  link="motor_fr"/>
    <origin xyz="0 0.02 -0.09" rpy="0 0 0"/>
  </joint>
  <link name="motor_fr">
    <visual>
      <geometry>
        <box size="0.075 0.09 0.09"/>
      </geometry>
      <material name="motor"/>
    </visual>
  </link>

  <joint name="wheel_fr_to_motor_fr" type="revolute">
    <parent link="motor_fr"/>
    <child  link="wheel_fr"/>
    <origin xyz="0 -0.09 0" rpy="0 0 0"/>
    <axis xyz="0 1 0"/>
    <limit lower="-3.1415" upper="3.1415" effort="0" velocity="0"/>
  </joint>
  <link name="wheel_fr">
    <visual>
      <geometry>
        <cylinder length="0.09" radius="0.1"/>
      </geometry>
      <origin xyz="0 0 0" rpy="1.57 0 0"/>
      <material name="wheel"/>
    </visual>
  </link> -->
  <!-- leg_br -->
  <joint name="frame1_br_to_base_link" type="fixed">
    <parent link="base_link"/>
    <child link="frame1_br"/>
    <origin rpy="0 0 0" xyz="0 -0.14 -0.1"/>
  </joint>
  <link name="frame1_br">
    <visual>
      <geometry>
        <box size="0.27 0.02 0.09"/>
      </geometry>
      <origin rpy="0 0 0" xyz="-0.135 0 0"/>
      <material name="frame"/>
    </visual>
  </link>
  <joint name="frame2_br_to_frame1_br" type="fixed">
    <parent link="frame1_br"/>
    <child link="frame2_br"/>
    <origin rpy="0 0 0" xyz="-0.23 -0.02 -0.045"/>
  </joint>
  <link name="frame2_br">
    <visual>
      <geometry>
        <box size="0.08 0.02 0.05"/>
      </geometry>
      <origin rpy="0 0 0" xyz="0 0 0"/>
      <material name="frame"/>
    </visual>
  </link>
  <!-- <joint name="gear_br_to_frame2_br" type="fixed">
    <parent link="frame2_br"/>
    <child  link="gear_br"/>
    <origin xyz="0 -0.035 -0.06" rpy="0 0 0"/>
  </joint>
  <link name="gear_br">
    <visual>
      <geometry>
        <box size="0.075 0.09 0.07"/>
      </geometry>
      <origin xyz="0 0 0" rpy="0 0 0"/>
      <material name="gear"/>
    </visual>
  </link>

  <joint name="frame3_br_to_gear_br" type="revolute">
    <parent link="gear_br"/>
    <child  link="frame3_br"/>
    <axis xyz="0 0 1"/>
    <origin xyz="0 0 -0.08" rpy="0 0 0"/>
    <limit lower="-3.1415" upper="3.1415" effort="0" velocity="0"/>
  </joint>
  <link name="frame3_br">
    <visual>
      <geometry>
        <box size="0.075 0.09 0.09"/>
      </geometry>
      <origin xyz="0 0 0" rpy="0 0 0"/>
      <material name="frame"/>
    </visual>
  </link>

  <joint name="motor_br_to_frame3_br" type="fixed">
    <parent link="frame3_br"/>
    <child  link="motor_br"/>
    <origin xyz="0 0.02 -0.09" rpy="0 0 0"/>
  </joint>
  <link name="motor_br">
    <visual>
      <geometry>
        <box size="0.075 0.09 0.09"/>
      </geometry>
      <material name="motor"/>
    </visual>
  </link>

  <joint name="wheel_br_to_motor_br" type="revolute">
    <parent link="motor_br"/>
    <child  link="wheel_br"/>
    <origin xyz="0 -0.09 0" rpy="0 0 0"/>
    <axis xyz="0 1 0"/>
    <limit lower="-3.1415" upper="3.1415" effort="0" velocity="0"/>
  </joint>
  <link name="wheel_br">
    <visual>
      <geometry>
        <cylinder length="0.09" radius="0.1"/>
      </geometry>
      <origin xyz="0 0 0" rpy="1.57 0 0"/>
      <material name="wheel"/>
    </visual>
  </link> -->
  <link name="right_front_wheel">
    <visual>
      <origin rpy="0 0 0" xyz="0 0 0"/>
      <geometry>
        <cylinder length="0.022" radius="0.011"/>
      </geometry>
      <material name="Black"/>
    </visual>
    <collision>
      <origin rpy="0 0 0" xyz="0 0 0"/>
      <geometry>
        <cylinder length="0.022" radius="0.011"/>
      </geometry>
    </collision>
    <inertial>
      <mass value="0.2"/>
      <inertia ixx="2.48722222222e-05" ixy="0.0" ixz="0.0" iyy="2.48722222222e-05" iyz="0.0" izz="3.36111111111e-05"/>
    </inertial>
  </link>
  <link name="right_front_wheel1">
    <visual>
      <origin rpy="1.57 0 0" xyz="0 0 0"/>
      <geometry>
        <mesh filename="package://diff_drive/meshes/tyre11.dae"/>
        <cylinder length="0.02" radius="0.05"/>
      </geometry>
      <material name="Black"/>
    </visual>
    <collision>
      <origin rpy="1.57 0 0" xyz="0 0 0"/>
      <geometry>
        <cylinder length="0.02" radius="0.05"/>
        <mesh filename="package://diff_drive/meshes/tyre11.dae"/>
      </geometry>
    </collision>
    <inertial>
      <mass value="0.2"/>
      <inertia ixx="0.000159316666667" ixy="0.0" ixz="0.0" iyy="0.000159316666667" iyz="0.0" izz="0.0003025"/>
    </inertial>
  </link>
  <gazebo reference="right_front_wheel1">
    <material>Gazebo/Black</material>
    <turnGravityOff>false</turnGravityOff>
  </gazebo>
  <joint name="right_front_wheel_joint1" type="fixed">
    <parent link="right_front_wheel"/>
    <child link="right_front_wheel1"/>
    <origin rpy="0 0 0" xyz="0 0 0"/>
  </joint>
  <gazebo reference="right_front_wheel">
    <mu1 value="200.0"/>
    <mu2 value="100.0"/>
    <kp value="10000000.0"/>
    <kd value="1.0"/>
    <material>Gazebo/Black</material>
  </gazebo>
  <joint name="right_front_wheel_joint" type="continuous">
    <parent link="frame2_fr"/>
    <child link="right_front_wheel"/>
    <origin rpy="0 0 0" xyz="0 -0.035  0.015"/>
    <axis xyz="0 1 0"/>
    <limit effort="100" velocity="100"/>
    <dynamics damping="0.0" friction="0.0"/>
  </joint>
  <transmission name="right_front_wheel_trans">
    <type>transmission_interface/SimpleTransmission</type>
    <actuator name="right_front_wheel_motor">
      <hardwareInterface>EffortJointInterface</hardwareInterface>
      <mechanicalReduction>1</mechanicalReduction>
    </actuator>
    <joint name="right_front_wheel_joint">
      <hardwareInterface>VelocityJointInterface</hardwareInterface>
    </joint>
  </transmission>
  <link name="right_back_wheel">
    <visual>
      <origin rpy="0 0 0" xyz="0 0 0"/>
      <geometry>
        <cylinder length="0.022" radius="0.011"/>
      </geometry>
      <material name="Black"/>
    </visual>
    <collision>
      <origin rpy="0 0 0" xyz="0 0 0"/>
      <geometry>
        <cylinder length="0.022" radius="0.011"/>
      </geometry>
    </collision>
    <inertial>
      <mass value="0.2"/>
      <inertia ixx="2.48722222222e-05" ixy="0.0" ixz="0.0" iyy="2.48722222222e-05" iyz="0.0" izz="3.36111111111e-05"/>
    </inertial>
  </link>
  <link name="right_back_wheel1">
    <visual>
      <origin rpy="1.57 0 0" xyz="0 0 0"/>
      <geometry>
        <mesh filename="package://diff_drive/meshes/tyre11.dae"/>
        <cylinder length="0.02" radius="0.05"/>
      </geometry>
      <material name="Black"/>
    </visual>
    <collision>
      <origin rpy="1.57 0 0" xyz="0 0 0"/>
      <geometry>
        <cylinder length="0.02" radius="0.05"/>
        <mesh filename="package://diff_drive/meshes/tyre11.dae"/>
      </geometry>
    </collision>
    <inertial>
      <mass value="0.2"/>
      <inertia ixx="0.000159316666667" ixy="0.0" ixz="0.0" iyy="0.000159316666667" iyz="0.0" izz="0.0003025"/>
    </inertial>
  </link>
  <gazebo reference="right_back_wheel1">
    <material>Gazebo/Black</material>
    <turnGravityOff>false</turnGravityOff>
  </gazebo>
  <joint name="right_back_wheel_joint1" type="fixed">
    <parent link="right_back_wheel"/>
    <child link="right_back_wheel1"/>
    <origin rpy="0 0 0" xyz="0 0 0"/>
  </joint>
  <gazebo reference="right_back_wheel">
    <mu1 value="200.0"/>
    <mu2 value="100.0"/>
    <kp value="10000000.0"/>
    <kd value="1.0"/>
    <material>Gazebo/Black</material>
  </gazebo>
  <joint name="right_back_wheel_joint" type="continuous">
    <parent link="frame2_br"/>
    <child link="right_back_wheel"/>
    <origin rpy="0 0 0" xyz="0 -0.035  0.015"/>
    <axis xyz="0 1 0"/>
    <limit effort="100" velocity="100"/>
    <dynamics damping="0.0" friction="0.0"/>
  </joint>
  <transmission name="right_back_wheel_trans">
    <type>transmission_interface/SimpleTransmission</type>
    <actuator name="right_back_wheel_motor">
      <hardwareInterface>EffortJointInterface</hardwareInterface>
      <mechanicalReduction>1</mechanicalReduction>
    </actuator>
    <joint name="right_back_wheel_joint">
      <hardwareInterface>VelocityJointInterface</hardwareInterface>
    </joint>
  </transmission>
  <link name="left_front_wheel">
    <visual>
      <origin rpy="0 0 0" xyz="0 0 0"/>
      <geometry>
        <cylinder length="0.022" radius="0.011"/>
      </geometry>
      <material name="Black"/>
    </visual>
    <collision>
      <origin rpy="0 0 0" xyz="0 0 0"/>
      <geometry>
        <cylinder length="0.022" radius="0.011"/>
      </geometry>
    </collision>
    <inertial>
      <mass value="0.2"/>
      <inertia ixx="2.48722222222e-05" ixy="0.0" ixz="0.0" iyy="2.48722222222e-05" iyz="0.0" izz="3.36111111111e-05"/>
    </inertial>
  </link>
  <link name="left_front_wheel1">
    <visual>
      <origin rpy="1.57 0 0" xyz="0 0 0"/>
      <geometry>
        <mesh filename="package://diff_drive/meshes/tyre11.dae"/>
        <cylinder length="0.02" radius="0.05"/>
      </geometry>
      <material name="Black"/>
    </visual>
    <collision>
      <origin rpy="1.57 0 0" xyz="0 0 0"/>
      <geometry>
        <cylinder length="0.02" radius="0.05"/>
        <mesh filename="package://diff_drive/meshes/tyre11.dae"/>
      </geometry>
    </collision>
    <inertial>
      <mass value="0.2"/>
      <inertia ixx="0.000159316666667" ixy="0.0" ixz="0.0" iyy="0.000159316666667" iyz="0.0" izz="0.0003025"/>
    </inertial>
  </link>
  <gazebo reference="left_front_wheel1">
    <material>Gazebo/Black</material>
    <turnGravityOff>false</turnGravityOff>
  </gazebo>
  <joint name="left_front_wheel_joint1" type="fixed">
    <parent link="left_front_wheel"/>
    <child link="left_front_wheel1"/>
    <origin rpy="0 0 0" xyz="0 0 0"/>
  </joint>
  <gazebo reference="left_front_wheel">
    <mu1 value="200.0"/>
    <mu2 value="100.0"/>
    <kp value="10000000.0"/>
    <kd value="1.0"/>
    <material>Gazebo/Black</material>
  </gazebo>
  <joint name="left_front_wheel_joint" type="continuous">
    <parent link="frame2_fl"/>
    <child link="left_front_wheel"/>
    <origin rpy="0 0 0" xyz="0 0.035  0.015"/>
    <axis xyz="0 1 0"/>
    <limit effort="100" velocity="100"/>
    <dynamics damping="0.0" friction="0.0"/>
  </joint>
  <transmission name="left_front_wheel_trans">
    <type>transmission_interface/SimpleTransmission</type>
    <actuator name="left_front_wheel_motor">
      <hardwareInterface>EffortJointInterface</hardwareInterface>
      <mechanicalReduction>1</mechanicalReduction>
    </actuator>
    <joint name="left_front_wheel_joint">
      <hardwareInterface>VelocityJointInterface</hardwareInterface>
    </joint>
  </transmission>
  <link name="left_back_wheel">
    <visual>
      <origin rpy="0 0 0" xyz="0 0 0"/>
      <geometry>
        <cylinder length="0.022" radius="0.011"/>
      </geometry>
      <material name="Black"/>
    </visual>
    <collision>
      <origin rpy="0 0 0" xyz="0 0 0"/>
      <geometry>
        <cylinder length="0.022" radius="0.011"/>
      </geometry>
    </collision>
    <inertial>
      <mass value="0.2"/>
      <inertia ixx="2.48722222222e-05" ixy="0.0" ixz="0.0" iyy="2.48722222222e-05" iyz="0.0" izz="3.36111111111e-05"/>
    </inertial>
  </link>
  <link name="left_back_wheel1">
    <visual>
      <origin rpy="1.57 0 0" xyz="0 0 0"/>
      <geometry>
        <mesh filename="package://diff_drive/meshes/tyre11.dae"/>
        <cylinder length="0.02" radius="0.05"/>
      </geometry>
      <material name="Black"/>
    </visual>
    <collision>
      <origin rpy="1.57 0 0" xyz="0 0 0"/>
      <geometry>
        <cylinder length="0.02" radius="0.05"/>
        <mesh filename="package://diff_drive/meshes/tyre11.dae"/>
      </geometry>
    </collision>
    <inertial>
      <mass value="0.2"/>
      <inertia ixx="0.000159316666667" ixy="0.0" ixz="0.0" iyy="0.000159316666667" iyz="0.0" izz="0.0003025"/>
    </inertial>
  </link>
  <gazebo reference="left_back_wheel1">
    <material>Gazebo/Black</material>
    <turnGravityOff>false</turnGravityOff>
  </gazebo>
  <joint name="left_back_wheel_joint1" type="fixed">
    <parent link="left_back_wheel"/>
    <child link="left_back_wheel1"/>
    <origin rpy="0 0 0" xyz="0 0 0"/>
  </joint>
  <gazebo reference="left_back_wheel">
    <mu1 value="200.0"/>
    <mu2 value="100.0"/>
    <kp value="10000000.0"/>
    <kd value="1.0"/>
    <material>Gazebo/Black</material>
  </gazebo>
  <joint name="left_back_wheel_joint" type="continuous">
    <parent link="frame2_bl"/>
    <child link="left_back_wheel"/>
    <origin rpy="0 0 0" xyz="0 0.035  0.015"/>
    <axis xyz="0 1 0"/>
    <limit effort="100" velocity="100"/>
    <dynamics damping="0.0" friction="0.0"/>
  </joint>
  <transmission name="left_back_wheel_trans">
    <type>transmission_interface/SimpleTransmission</type>
    <actuator name="left_back_wheel_motor">
      <hardwareInterface>EffortJointInterface</hardwareInterface>
      <mechanicalReduction>1</mechanicalReduction>
    </actuator>
    <joint name="left_back_wheel_joint">
      <hardwareInterface>VelocityJointInterface</hardwareInterface>
    </joint>
  </transmission>
  <gazebo>
    <plugin filename="libgazebo_ros_control.so" name="gazebo_ros_control">
      <robotNamespace>/</robotNamespace>
    </plugin>
  </gazebo>
</robot>

