<sdf version='1.6'>
  <world name='default'>
    <light name='sun' type='directional'>
      <cast_shadows>1</cast_shadows>
      <pose frame=''>0 0 10 0 -0 0</pose>
      <diffuse>0.8 0.8 0.8 1</diffuse>
      <specular>0.2 0.2 0.2 1</specular>
      <attenuation>
        <range>1000</range>
        <constant>0.9</constant>
        <linear>0.01</linear>
        <quadratic>0.001</quadratic>
      </attenuation>
      <direction>-0.5 0.1 -0.9</direction>
    </light>
    <model name='ground_plane'>
      <static>1</static>
      <link name='link'>
        <collision name='collision'>
          <geometry>
            <plane>
              <normal>0 0 1</normal>
              <size>100 100</size>
            </plane>
          </geometry>
          <surface>
            <contact>
              <collide_bitmask>65535</collide_bitmask>
              <ode/>
            </contact>
            <friction>
              <ode>
                <mu>100</mu>
                <mu2>50</mu2>
              </ode>
              <torsional>
                <ode/>
              </torsional>
            </friction>
            <bounce/>
          </surface>
          <max_contacts>10</max_contacts>
        </collision>
        <visual name='visual'>
          <cast_shadows>0</cast_shadows>
          <geometry>
            <plane>
              <normal>0 0 1</normal>
              <size>100 100</size>
            </plane>
          </geometry>
          <material>
            <script>
              <uri>file://media/materials/scripts/gazebo.material</uri>
              <name>Gazebo/Grey</name>
            </script>
          </material>
        </visual>
        <self_collide>0</self_collide>
        <enable_wind>0</enable_wind>
        <kinematic>0</kinematic>
      </link>
    </model>
    <gravity>0 0 -9.8</gravity>
    <magnetic_field>6e-06 2.3e-05 -4.2e-05</magnetic_field>
    <atmosphere type='adiabatic'/>
    <physics name='default_physics' default='0' type='ode'>
      <max_step_size>0.001</max_step_size>
      <real_time_factor>1</real_time_factor>
      <real_time_update_rate>1000</real_time_update_rate>
    </physics>
    <scene>
      <ambient>0.4 0.4 0.4 1</ambient>
      <background>0.7 0.7 0.7 1</background>
      <shadows>1</shadows>
    </scene>
    <audio>
      <device>default</device>
    </audio>
    <wind/>
    <spherical_coordinates>
      <surface_model>EARTH_WGS84</surface_model>
      <latitude_deg>0</latitude_deg>
      <longitude_deg>0</longitude_deg>
      <elevation>0</elevation>
      <heading_deg>0</heading_deg>
    </spherical_coordinates>
    <model name='Diff_Drive'>
      <link name='base_link'>
        <pose frame=''>0 0 0 0 -0 0</pose>
        <inertial>
          <pose frame=''>0 0 0 0 -0 0</pose>
          <mass>5.00001</mass>
          <inertia>
            <ixx>1</ixx>
            <ixy>0</ixy>
            <ixz>-2.59999e-08</ixz>
            <iyy>1</iyy>
            <iyz>0</iyz>
            <izz>1</izz>
          </inertia>
        </inertial>
        <collision name='base_link_collision'>
          <pose frame=''>0 0 0 -1.57 0 0</pose>
          <geometry>
            <mesh>
              <scale>1 1 1</scale>
              <uri>/home/wayo/catkin_ws/src/pf1_dev/robot_arm_ros/diff_drive/meshes/base assembly.dae</uri>
            </mesh>
          </geometry>
          <surface>
            <contact>
              <ode/>
            </contact>
            <friction>
              <ode/>
              <torsional>
                <ode/>
              </torsional>
            </friction>
            <bounce/>
          </surface>
          <max_contacts>10</max_contacts>
        </collision>
        <collision name='base_link_fixed_joint_lump__hokuyo_sensor_collision_1'>
          <pose frame=''>0.02 0 0.13 0 -0 0</pose>
          <geometry>
            <box>
              <size>0.1 0.1 0.1</size>
            </box>
          </geometry>
          <surface>
            <contact>
              <ode/>
            </contact>
            <friction>
              <ode/>
              <torsional>
                <ode/>
              </torsional>
            </friction>
            <bounce/>
          </surface>
          <max_contacts>10</max_contacts>
        </collision>
        <visual name='base_link_visual'>
          <pose frame=''>0 0 0 -1.57 0 0</pose>
          <geometry>
            <mesh>
              <scale>1 1 1</scale>
              <uri>/home/wayo/catkin_ws/src/pf1_dev/robot_arm_ros/diff_drive/meshes/base assembly.dae</uri>
            </mesh>
          </geometry>
          <material>
            <script>
              <uri>__default__</uri>
              <name>__default__</name>
            </script>
          </material>
        </visual>
        <visual name='base_link_fixed_joint_lump__camera_link_visual_1'>
          <pose frame=''>0.05 0 0.05 -1.5708 -0 -1.5708</pose>
          <geometry>
            <mesh>
              <scale>1 1 1</scale>
              <uri>/home/wayo/catkin_ws/src/pf1_dev/openni_camera/openni_description/mesh/kinect.dae</uri>
            </mesh>
          </geometry>
          <material>
            <script>
              <uri>__default__</uri>
              <name>__default__</name>
            </script>
          </material>
        </visual>
        <visual name='base_link_fixed_joint_lump__hokuyo_sensor_visual_2'>
          <pose frame=''>0.02 0 0.13 0 -0 0</pose>
          <geometry>
            <mesh>
              <scale>1 1 1</scale>
              <uri>/home/wayo/catkin_ws/src/pf1_dev/gazebo_ros_demos/rrbot_description/meshes/hokuyo.dae</uri>
            </mesh>
          </geometry>
          <material>
            <script>
              <uri>__default__</uri>
              <name>__default__</name>
            </script>
          </material>
        </visual>
        <velocity_decay/>
        <velocity_decay/>
        <sensor name='camera' type='depth'>
          <always_on>1</always_on>
          <visualize>1</visualize>
          <update_rate>20</update_rate>
          <camera name='__default__'>
            <pose frame=''>0 0 0 -1.57079 -1.57079 3.14159</pose>
            <horizontal_fov>1.0472</horizontal_fov>
            <image>
              <format>B8G8R8</format>
              <width>640</width>
              <height>480</height>
            </image>
            <clip>
              <near>0.05</near>
              <far>8</far>
            </clip>
          </camera>
          <plugin name='kinect_camera_controller' filename='libgazebo_ros_openni_kinect.so'>
            <cameraName>camera</cameraName>
            <alwaysOn>1</alwaysOn>
            <updateRate>10</updateRate>
            <imageTopicName>rgb/image_raw</imageTopicName>
            <depthImageTopicName>depth/image_raw</depthImageTopicName>
            <pointCloudTopicName>depth/points</pointCloudTopicName>
            <cameraInfoTopicName>rgb/camera_info</cameraInfoTopicName>
            <depthImageCameraInfoTopicName>depth/camera_info</depthImageCameraInfoTopicName>
            <frameName>camera_link</frameName>
            <baseline>0.1</baseline>
            <distortion_k1>0.0</distortion_k1>
            <distortion_k2>0.0</distortion_k2>
            <distortion_k3>0.0</distortion_k3>
            <distortion_t1>0.0</distortion_t1>
            <distortion_t2>0.0</distortion_t2>
            <pointCloudCutoff>0.4</pointCloudCutoff>
            <robotNamespace>/</robotNamespace>
          </plugin>
          <pose frame=''>0.05 0 0.05 -1.5708 -0 -1.5708</pose>
        </sensor>
        <velocity_decay/>
        <sensor name='base_link_hokuyo_sensor' type='gpu_ray'>
          <visualize>0</visualize>
          <update_rate>40</update_rate>
          <ray>
            <scan>
              <horizontal>
                <samples>400</samples>
                <resolution>1</resolution>
                <min_angle>-2.61799</min_angle>
                <max_angle>2.61799</max_angle>
              </horizontal>
            </scan>
            <range>
              <min>0.1</min>
              <max>30</max>
              <resolution>0.01</resolution>
            </range>
            <noise>
              <type>gaussian</type>
              <stddev>0.01</stddev>
            </noise>
          </ray>
          <plugin name='gazebo_ros_lidar_controller' filename='libgazebo_ros_gpu_laser.so'>
            <topicName>/scan</topicName>
            <frameName>hokuyo_sensor</frameName>
            <robotNamespace>/</robotNamespace>
          </plugin>
          <pose frame=''>0.02 0 0.13 0 -0 0</pose>
        </sensor>
        <gravity>1</gravity>
        <velocity_decay/>
        <gravity>1</gravity>
        <sensor name='imu_sensor' type='imu'>
          <always_on>1</always_on>
          <update_rate>100</update_rate>
          <visualize>1</visualize>
          <topic>data</topic>
          <plugin name='imu_plugin' filename='libgazebo_ros_imu_sensor.so'>
            <topicName>imu/data</topicName>
            <bodyName>imu_link</bodyName>
            <updateRateHZ>10.0</updateRateHZ>
            <gaussianNoise>0.0</gaussianNoise>
            <xyzOffset>0 0 0</xyzOffset>
            <rpyOffset>0 0 0</rpyOffset>
            <frameName>imu_link</frameName>
            <robotNamespace>/</robotNamespace>
          </plugin>
          <pose frame=''>0 0 0 0 -0 0</pose>
          <imu/>
        </sensor>
        <self_collide>0</self_collide>
        <enable_wind>0</enable_wind>
        <kinematic>0</kinematic>
      </link>
      <link name='left_back_wheel'>
        <pose frame=''>-0.058 0.115 0.015 0 -0 0</pose>
        <inertial>
          <pose frame=''>0 0 0 0 -0 0</pose>
          <mass>0.4</mass>
          <inertia>
            <ixx>0.000184189</ixx>
            <ixy>0</ixy>
            <ixz>0</ixz>
            <iyy>0.000184189</iyy>
            <iyz>0</iyz>
            <izz>0.000336111</izz>
          </inertia>
        </inertial>
        <collision name='left_back_wheel_collision'>
          <pose frame=''>0 0 0 1.57 -0 0</pose>
          <geometry>
            <cylinder>
              <length>0.022</length>
              <radius>0.011</radius>
            </cylinder>
          </geometry>
          <surface>
            <contact>
              <ode>
                <kp>1e+07</kp>
                <kd>1</kd>
              </ode>
            </contact>
            <friction>
              <ode>
                <mu>200</mu>
                <mu2>100</mu2>
              </ode>
              <torsional>
                <ode/>
              </torsional>
            </friction>
            <bounce/>
          </surface>
          <max_contacts>10</max_contacts>
        </collision>
        <collision name='left_back_wheel1_collision_1'>
          <pose frame=''>0 0 0 1.57 -0 0</pose>
          <geometry>
            <cylinder>
              <length>0.02</length>
              <radius>0.05</radius>
            </cylinder>
          </geometry>
          <surface>
            <contact>
              <ode>
                <kp>1e+07</kp>
                <kd>1</kd>
              </ode>
            </contact>
            <friction>
              <ode>
                <mu>200</mu>
                <mu2>100</mu2>
              </ode>
              <torsional>
                <ode/>
              </torsional>
            </friction>
            <bounce/>
          </surface>
          <max_contacts>10</max_contacts>
        </collision>
        <visual name='left_back_wheel_visual'>
          <pose frame=''>0 0 0 1.57 -0 0</pose>
          <geometry>
            <cylinder>
              <length>0.022</length>
              <radius>0.011</radius>
            </cylinder>
          </geometry>
          <material>
            <script>
              <name>Gazebo/Black</name>
              <uri>file://media/materials/scripts/gazebo.material</uri>
            </script>
          </material>
        </visual>
        <visual name='left_back_wheel1_visual_1'>
          <pose frame=''>0 0 0 1.57 -0 0</pose>
          <geometry>
            <cylinder>
              <length>0.02</length>
              <radius>0.05</radius>
            </cylinder>
          </geometry>
          <material>
            <script>
              <name>Gazebo/Black</name>
              <uri>file://media/materials/scripts/gazebo.material</uri>
            </script>
          </material>
        </visual>
        <velocity_decay/>
        <gravity>1</gravity>
        <velocity_decay/>
        <self_collide>0</self_collide>
        <enable_wind>0</enable_wind>
        <kinematic>0</kinematic>
      </link>
      <joint name='left_back_wheel_joint' type='revolute'>
        <child>left_back_wheel</child>
        <parent>base_link</parent>
        <axis>
          <xyz>0 1 0</xyz>
          <limit>
            <lower>-1e+16</lower>
            <upper>1e+16</upper>
          </limit>
          <dynamics>
            <damping>0</damping>
            <friction>0</friction>
            <spring_reference>0</spring_reference>
            <spring_stiffness>0</spring_stiffness>
          </dynamics>
          <use_parent_model_frame>1</use_parent_model_frame>
        </axis>
      </joint>
      <link name='left_front_wheel'>
        <pose frame=''>0.062 0.115 0.015 0 -0 0</pose>
        <inertial>
          <pose frame=''>0 0 0 0 -0 0</pose>
          <mass>0.4</mass>
          <inertia>
            <ixx>0.000184189</ixx>
            <ixy>0</ixy>
            <ixz>0</ixz>
            <iyy>0.000184189</iyy>
            <iyz>0</iyz>
            <izz>0.000336111</izz>
          </inertia>
        </inertial>
        <collision name='left_front_wheel_collision'>
          <pose frame=''>0 0 0 1.57 -0 0</pose>
          <geometry>
            <cylinder>
              <length>0.022</length>
              <radius>0.011</radius>
            </cylinder>
          </geometry>
          <surface>
            <contact>
              <ode>
                <kp>1e+07</kp>
                <kd>1</kd>
              </ode>
            </contact>
            <friction>
              <ode>
                <mu>200</mu>
                <mu2>100</mu2>
              </ode>
              <torsional>
                <ode/>
              </torsional>
            </friction>
            <bounce/>
          </surface>
          <max_contacts>10</max_contacts>
        </collision>
        <collision name='left_front_wheel1_collision_1'>
          <pose frame=''>0 0 0 1.57 -0 0</pose>
          <geometry>
            <cylinder>
              <length>0.02</length>
              <radius>0.05</radius>
            </cylinder>
          </geometry>
          <surface>
            <contact>
              <ode>
                <kp>1e+07</kp>
                <kd>1</kd>
              </ode>
            </contact>
            <friction>
              <ode>
                <mu>200</mu>
                <mu2>100</mu2>
              </ode>
              <torsional>
                <ode/>
              </torsional>
            </friction>
            <bounce/>
          </surface>
          <max_contacts>10</max_contacts>
        </collision>
        <visual name='left_front_wheel_visual'>
          <pose frame=''>0 0 0 1.57 -0 0</pose>
          <geometry>
            <cylinder>
              <length>0.022</length>
              <radius>0.011</radius>
            </cylinder>
          </geometry>
          <material>
            <script>
              <name>Gazebo/Black</name>
              <uri>file://media/materials/scripts/gazebo.material</uri>
            </script>
          </material>
        </visual>
        <visual name='left_front_wheel1_visual_1'>
          <pose frame=''>0 0 0 1.57 -0 0</pose>
          <geometry>
            <cylinder>
              <length>0.02</length>
              <radius>0.05</radius>
            </cylinder>
          </geometry>
          <material>
            <script>
              <name>Gazebo/Black</name>
              <uri>file://media/materials/scripts/gazebo.material</uri>
            </script>
          </material>
        </visual>
        <velocity_decay/>
        <gravity>1</gravity>
        <velocity_decay/>
        <self_collide>0</self_collide>
        <enable_wind>0</enable_wind>
        <kinematic>0</kinematic>
      </link>
      <joint name='left_front_wheel_joint' type='revolute'>
        <child>left_front_wheel</child>
        <parent>base_link</parent>
        <axis>
          <xyz>0 1 0</xyz>
          <limit>
            <lower>-1e+16</lower>
            <upper>1e+16</upper>
          </limit>
          <dynamics>
            <damping>0</damping>
            <friction>0</friction>
            <spring_reference>0</spring_reference>
            <spring_stiffness>0</spring_stiffness>
          </dynamics>
          <use_parent_model_frame>1</use_parent_model_frame>
        </axis>
      </joint>
      <link name='right_back_wheel'>
        <pose frame=''>-0.058 -0.115 0.015 0 -0 0</pose>
        <inertial>
          <pose frame=''>0 0 0 0 -0 0</pose>
          <mass>0.4</mass>
          <inertia>
            <ixx>0.000184189</ixx>
            <ixy>0</ixy>
            <ixz>0</ixz>
            <iyy>0.000184189</iyy>
            <iyz>0</iyz>
            <izz>0.000336111</izz>
          </inertia>
        </inertial>
        <collision name='right_back_wheel_collision'>
          <pose frame=''>0 0 0 1.57 -0 0</pose>
          <geometry>
            <cylinder>
              <length>0.022</length>
              <radius>0.011</radius>
            </cylinder>
          </geometry>
          <surface>
            <contact>
              <ode>
                <kp>1e+07</kp>
                <kd>1</kd>
              </ode>
            </contact>
            <friction>
              <ode>
                <mu>200</mu>
                <mu2>100</mu2>
              </ode>
              <torsional>
                <ode/>
              </torsional>
            </friction>
            <bounce/>
          </surface>
          <max_contacts>10</max_contacts>
        </collision>
        <collision name='right_back_wheel1_collision_1'>
          <pose frame=''>0 0 0 1.57 -0 0</pose>
          <geometry>
            <cylinder>
              <length>0.02</length>
              <radius>0.05</radius>
            </cylinder>
          </geometry>
          <surface>
            <contact>
              <ode>
                <kp>1e+07</kp>
                <kd>1</kd>
              </ode>
            </contact>
            <friction>
              <ode>
                <mu>200</mu>
                <mu2>100</mu2>
              </ode>
              <torsional>
                <ode/>
              </torsional>
            </friction>
            <bounce/>
          </surface>
          <max_contacts>10</max_contacts>
        </collision>
        <visual name='right_back_wheel_visual'>
          <pose frame=''>0 0 0 1.57 -0 0</pose>
          <geometry>
            <cylinder>
              <length>0.022</length>
              <radius>0.011</radius>
            </cylinder>
          </geometry>
          <material>
            <script>
              <name>Gazebo/Black</name>
              <uri>file://media/materials/scripts/gazebo.material</uri>
            </script>
          </material>
        </visual>
        <visual name='right_back_wheel1_visual_1'>
          <pose frame=''>0 0 0 1.57 -0 0</pose>
          <geometry>
            <cylinder>
              <length>0.02</length>
              <radius>0.05</radius>
            </cylinder>
          </geometry>
          <material>
            <script>
              <name>Gazebo/Black</name>
              <uri>file://media/materials/scripts/gazebo.material</uri>
            </script>
          </material>
        </visual>
        <velocity_decay/>
        <gravity>1</gravity>
        <velocity_decay/>
        <self_collide>0</self_collide>
        <enable_wind>0</enable_wind>
        <kinematic>0</kinematic>
      </link>
      <joint name='right_back_wheel_joint' type='revolute'>
        <child>right_back_wheel</child>
        <parent>base_link</parent>
        <axis>
          <xyz>0 1 0</xyz>
          <limit>
            <lower>-1e+16</lower>
            <upper>1e+16</upper>
          </limit>
          <dynamics>
            <damping>0</damping>
            <friction>0</friction>
            <spring_reference>0</spring_reference>
            <spring_stiffness>0</spring_stiffness>
          </dynamics>
          <use_parent_model_frame>1</use_parent_model_frame>
        </axis>
      </joint>
      <link name='right_front_wheel'>
        <pose frame=''>0.062 -0.115 0.015 0 -0 0</pose>
        <inertial>
          <pose frame=''>0 0 0 0 -0 0</pose>
          <mass>0.4</mass>
          <inertia>
            <ixx>0.000184189</ixx>
            <ixy>0</ixy>
            <ixz>0</ixz>
            <iyy>0.000184189</iyy>
            <iyz>0</iyz>
            <izz>0.000336111</izz>
          </inertia>
        </inertial>
        <collision name='right_front_wheel_collision'>
          <pose frame=''>0 0 0 1.57 -0 0</pose>
          <geometry>
            <cylinder>
              <length>0.022</length>
              <radius>0.011</radius>
            </cylinder>
          </geometry>
          <surface>
            <contact>
              <ode>
                <kp>1e+07</kp>
                <kd>1</kd>
              </ode>
            </contact>
            <friction>
              <ode>
                <mu>200</mu>
                <mu2>100</mu2>
              </ode>
              <torsional>
                <ode/>
              </torsional>
            </friction>
            <bounce/>
          </surface>
          <max_contacts>10</max_contacts>
        </collision>
        <collision name='right_front_wheel1_collision_1'>
          <pose frame=''>0 0 0 1.57 -0 0</pose>
          <geometry>
            <cylinder>
              <length>0.02</length>
              <radius>0.05</radius>
            </cylinder>
          </geometry>
          <surface>
            <contact>
              <ode>
                <kp>1e+07</kp>
                <kd>1</kd>
              </ode>
            </contact>
            <friction>
              <ode>
                <mu>200</mu>
                <mu2>100</mu2>
              </ode>
              <torsional>
                <ode/>
              </torsional>
            </friction>
            <bounce/>
          </surface>
          <max_contacts>10</max_contacts>
        </collision>
        <visual name='right_front_wheel_visual'>
          <pose frame=''>0 0 0 1.57 -0 0</pose>
          <geometry>
            <cylinder>
              <length>0.022</length>
              <radius>0.011</radius>
            </cylinder>
          </geometry>
          <material>
            <script>
              <name>Gazebo/Black</name>
              <uri>file://media/materials/scripts/gazebo.material</uri>
            </script>
          </material>
        </visual>
        <visual name='right_front_wheel1_visual_1'>
          <pose frame=''>0 0 0 1.57 -0 0</pose>
          <geometry>
            <cylinder>
              <length>0.02</length>
              <radius>0.05</radius>
            </cylinder>
          </geometry>
          <material>
            <script>
              <name>Gazebo/Black</name>
              <uri>file://media/materials/scripts/gazebo.material</uri>
            </script>
          </material>
        </visual>
        <velocity_decay/>
        <gravity>1</gravity>
        <velocity_decay/>
        <self_collide>0</self_collide>
        <enable_wind>0</enable_wind>
        <kinematic>0</kinematic>
      </link>
      <joint name='right_front_wheel_joint' type='revolute'>
        <child>right_front_wheel</child>
        <parent>base_link</parent>
        <axis>
          <xyz>0 1 0</xyz>
          <limit>
            <lower>-1e+16</lower>
            <upper>1e+16</upper>
          </limit>
          <dynamics>
            <damping>0</damping>
            <friction>0</friction>
            <spring_reference>0</spring_reference>
            <spring_stiffness>0</spring_stiffness>
          </dynamics>
          <use_parent_model_frame>1</use_parent_model_frame>
        </axis>
      </joint>
      <static>0</static>
      <plugin name='gazebo_ros_control' filename='libgazebo_ros_control.so'>
        <robotNamespace>/</robotNamespace>
      </plugin>
      <pose frame=''>0 0 1 0 -0 0</pose>
    </model>
    
    
 <actor name="actor1">
     <skin>
        <filename>walk.dae</filename>
        <scale>1.0</scale>
     </skin>

     <animation name="walking">
        <filename>walk.dae</filename>
        <scale>1.000000</scale>
        <interpolate_x>true</interpolate_x>
     </animation>

     <script>
        <loop>true</loop>
        <delay_start>0.000000</delay_start>
        <auto_start>true</auto_start>
        <trajectory id="0" type="walking">
           <waypoint>
              <time>0.000000</time>
              <pose>5.8 1.2 0.15 0.000000 0.000000 0</pose>
           </waypoint>
           <waypoint>
              <time>16.000000</time>
              <pose>15.12 1.2 0.15 0.000000 0.000000 0</pose>
           </waypoint>
           <waypoint>
              <time>17.00000</time>
              <pose>15.21 1.2 0.15 0.000000 0.000000 3.14519</pose>
           </waypoint>
           <waypoint>
              <time>26.000000</time>
              <pose>5.8 1.2 0.15 0.000000 0.000000 3.14519</pose>
           </waypoint>
           <waypoint>
              <time>26.500000</time>
              <pose>5.8 1.2 0.15 0.000000 0.000000 0</pose>
           </waypoint>
        </trajectory>
     </script>

  <link name="link">

      <inertial>
    <pose>0 0 0.95 0 0 0</pose>
    <mass>80.0</mass>
    <inertia>
      <ixx>27.82</ixx>
      <ixy>0</ixy>
      <ixz>0</ixz>
      <iyy>24.88</iyy>
      <iyz>0</iyz>
      <izz>4.57</izz>
    </inertia>
      </inertial>

      <collision name="bottom">
    <pose>0 0 0 0 0 0</pose>
    <geometry>
      <box>
        <size>0.35 0.75 0.02</size>
      </box>
    </geometry>
      </collision>
  </link>
 </actor>


<actor name="actor2">
  <skin>
        <filename>walk.dae</filename>
        <scale>1.0</scale>
     </skin>

     <animation name="walking">
        <filename>walk.dae</filename>
        <scale>1.000000</scale>
        <interpolate_x>true</interpolate_x>
     </animation>

     <script>
        <loop>true</loop>
        <delay_start>0.000000</delay_start>
        <auto_start>true</auto_start>
        <trajectory id="0" type="walking">
           <waypoint>
              <time>0.000000</time>
              <pose>5.8 -1 0.15 0.000000 0.000000 0</pose>
           </waypoint>
           <waypoint>
              <time>17.000000</time>
              <pose>15.12 -1 0.15 0.000000 0.000000 0</pose>
           </waypoint>
           <waypoint>
              <time>17.20000</time>
              <pose>15.21 -1 0.15 0.000000 0.000000 3.14519</pose>
           </waypoint>
           <waypoint>
              <time>26.200000</time>
              <pose>5.8 -1 0.15 0.000000 0.000000 3.14519</pose>
           </waypoint>
           <waypoint>
              <time>26.500000</time>
              <pose>5.8 -1 0.15 0.000000 0.000000 0</pose>
           </waypoint>
        </trajectory>
     </script>

  <link name="link">

      <inertial>
    <pose>0 0 0.95 0 0 0</pose>
    <mass>80.0</mass>
    <inertia>
      <ixx>27.82</ixx>
      <ixy>0</ixy>
      <ixz>0</ixz>
      <iyy>24.88</iyy>
      <iyz>0</iyz>
      <izz>4.57</izz>
    </inertia>
      </inertial>

      <collision name="bottom">
    <pose>0 0 0 0 0 0</pose>
    <geometry>
      <box>
        <size>0.35 0.75 0.02</size>
      </box>
    </geometry>
      </collision>
  </link>
 </actor>


<actor name="actor3">
     <skin>
        <filename>walk.dae</filename>
        <scale>1.0</scale>
     </skin>

     <animation name="walking">
        <filename>walk.dae</filename>
        <scale>1.000000</scale>
        <interpolate_x>true</interpolate_x>
     </animation>

     <script>
        <loop>true</loop>
        <delay_start>0.000000</delay_start>
        <auto_start>true</auto_start>
        <trajectory id="0" type="walking">
           <waypoint>
              <time>0.000000</time>
              <pose>15.12 0 0.15 0.000000 0.000000 0</pose>
           </waypoint>
           <waypoint>
              <time>16.000000</time>
              <pose>5.12 0 0.15 0.000000 0.000000 0</pose>
           </waypoint>
           <waypoint>
              <time>16.50000</time>
              <pose>5.21 0 0.15 0.000000 0.000000 3.14519</pose>
           </waypoint>
           <waypoint>
              <time>26.000000</time>
              <pose> 15.12 0 0.15 0.000000 0.000000 3.14519</pose>
           </waypoint>
           <waypoint>
              <time>26.500000</time>
              <pose>15.12 0 0.15 0.000000 0.000000 0</pose>
           </waypoint>
        </trajectory>
     </script>

  <link name="link">

      <inertial>
    <pose>0 0 0.95 0 0 0</pose>
    <mass>80.0</mass>
    <inertia>
      <ixx>27.82</ixx>
      <ixy>0</ixy>
      <ixz>0</ixz>
      <iyy>24.88</iyy>
      <iyz>0</iyz>
      <izz>4.57</izz>
    </inertia>
      </inertial>

      <collision name="bottom">
    <pose>0 0 0 0 0 0</pose>
    <geometry>
      <box>
        <size>0.35 0.75 0.02</size>
      </box>
    </geometry>
      </collision>
  </link>
 </actor>


<actor name="actor4">
     <skin>
        <filename>walk.dae</filename>
        <scale>1.0</scale>
     </skin>

     <animation name="walking">
        <filename>walk.dae</filename>
        <scale>1.000000</scale>
        <interpolate_x>true</interpolate_x>
     </animation>

     <script>
        <loop>true</loop>
        <delay_start>0.000000</delay_start>
        <auto_start>true</auto_start>
        <trajectory id="0" type="walking">
           <waypoint>
              <time>0.000000</time>
              <pose>0 1.2 0.15 0.000000 0.000000 0</pose>
           </waypoint>
           <waypoint>
              <time>16.000000</time>
              <pose>10.12 1.2 0.15 0.000000 0.000000 0</pose>
           </waypoint>
           <waypoint>
              <time>17.00000</time>
              <pose>10.21 1.2 0.15 0.000000 0.000000 3.14519</pose>
           </waypoint>
           <waypoint>
              <time>26.000000</time>
              <pose>0 1.2 0.15 0.000000 0.000000 3.14519</pose>
           </waypoint>
           <waypoint>
              <time>26.500000</time>
              <pose>0 1.2 0.15 0.000000 0.000000 0</pose>
           </waypoint>
        </trajectory>
     </script>

  <link name="link">

      <inertial>
    <pose>0 0 0.95 0 0 0</pose>
    <mass>80.0</mass>
    <inertia>
      <ixx>27.82</ixx>
      <ixy>0</ixy>
      <ixz>0</ixz>
      <iyy>24.88</iyy>
      <iyz>0</iyz>
      <izz>4.57</izz>
    </inertia>
      </inertial>

      <collision name="bottom">
    <pose>0 0 0 0 0 0</pose>
    <geometry>
      <box>
        <size>0.35 0.75 0.02</size>
      </box>
    </geometry>
      </collision>
  </link>
 </actor>



    
    <state world_name='default'>
      <sim_time>17 172000000</sim_time>
      <real_time>23 164381000</real_time>
      <wall_time>1627708061 177601500</wall_time>
      <iterations>17172</iterations>
      <model name='Diff_Drive'>
        <pose frame=''>-2.7e-05 -0.000154 0.035006 1e-06 -1e-06 9.9e-05</pose>
        <scale>1 1 1</scale>
        <link name='base_link'>
          <pose frame=''>-2.7e-05 -0.000154 0.035006 1e-06 -1e-06 9.9e-05</pose>
          <velocity>-1e-06 -8e-06 1.4e-05 -3e-06 -0 3e-06</velocity>
          <acceleration>0 -0 0 -0 -0 -0</acceleration>
          <wrench>0 -0 0 0 -0 0</wrench>
        </link>
        <link name='left_back_wheel'>
          <pose frame=''>-0.058038 0.114841 0.050006 4.8e-05 -0.000883 9.9e-05</pose>
          <velocity>-2e-06 -8e-06 1.4e-05 5e-06 -3.5e-05 3e-06</velocity>
          <acceleration>0 -0 0 0 -0 0</acceleration>
          <wrench>0 -0 0 0 -0 0</wrench>
        </link>
        <link name='left_front_wheel'>
          <pose frame=''>0.061962 0.114852 0.050006 4.5e-05 -0.000517 9.9e-05</pose>
          <velocity>-2e-06 -8e-06 1.3e-05 4e-06 -3.5e-05 3e-06</velocity>
          <acceleration>0 -0 0 0 -0 0</acceleration>
          <wrench>0 -0 0 0 -0 0</wrench>
        </link>
        <link name='right_back_wheel'>
          <pose frame=''>-0.058016 -0.115159 0.050006 4.9e-05 -0.000418 9.9e-05</pose>
          <velocity>-1e-06 -8e-06 1.5e-05 6e-06 -2.1e-05 3e-06</velocity>
          <acceleration>0 -0 0 0 -0 0</acceleration>
          <wrench>0 -0 0 0 -0 0</wrench>
        </link>
        <link name='right_front_wheel'>
          <pose frame=''>0.061984 -0.115148 0.050006 4.6e-05 -0.00027 9.9e-05</pose>
          <velocity>-1e-06 -8e-06 1.4e-05 5e-06 -2.1e-05 3e-06</velocity>
          <acceleration>0 -0 0 0 -0 0</acceleration>
          <wrench>0 -0 0 0 -0 0</wrench>
        </link>
      </model>
      <model name='ground_plane'>
        <pose frame=''>0 0 0 0 -0 0</pose>
        <scale>1 1 1</scale>
        <link name='link'>
          <pose frame=''>0 0 0 0 -0 0</pose>
          <velocity>0 0 0 0 -0 0</velocity>
          <acceleration>0 0 0 0 -0 0</acceleration>
          <wrench>0 0 0 0 -0 0</wrench>
        </link>
      </model>

      
      <light name='sun'>
        <pose frame=''>0 0 10 0 -0 0</pose>
      </light>
    </state>
    <gui fullscreen='0'>
      <camera name='user_camera'>
        <pose frame=''>7.51 -5.00929 3.23628 0 0.275643 2.35619</pose>
        <view_controller>orbit</view_controller>
        <projection_type>perspective</projection_type>
      </camera>
    </gui>
  </world>
</sdf>
